2025-01-27 16:46:03,297 - root - INFO - User Manju4 authenticated successfully.
2025-01-27 16:48:10,192 - root - INFO - Database 'buup' already exists.
2025-01-27 16:48:10,195 - root - INFO - No roles found for this Org.
2025-01-27 16:49:03,765 - root - ERROR - Error while creating Role: 'spaceId'
2025-01-27 16:52:25,665 - root - INFO - User Manju4 authenticated successfully.
2025-01-27 16:52:30,215 - root - INFO - Database 'buup' already exists.
2025-01-27 16:52:30,259 - root - INFO - Role test created successfully
2025-01-27 16:52:44,158 - root - ERROR - Error while creating Role: 'spaceId'
2025-01-27 16:53:51,812 - root - INFO - Database 'buup' already exists.
2025-01-27 16:53:51,815 - root - INFO - No roles found for this Org.
2025-01-27 16:54:07,656 - root - INFO - Database 'buup' already exists.
2025-01-27 16:55:43,962 - root - ERROR - Error while creating Role: 'spaceId'
2025-01-27 16:56:14,906 - root - INFO - Database 'buup' already exists.
2025-01-27 19:32:28,414 - root - INFO - User Manju4 authenticated successfully.
2025-01-27 19:37:07,301 - root - INFO - User Manju4 authenticated successfully.
2025-01-27 19:39:02,902 - root - INFO - User Manju4 authenticated successfully.
2025-01-27 19:40:19,534 - root - INFO - User Manju4 authenticated successfully.
2025-01-27 19:41:36,356 - root - INFO - Database 'buup' already exists.
2025-01-27 19:43:03,048 - root - INFO - Database 'buup' already exists.
2025-01-27 19:53:25,001 - root - INFO - User Manju4 authenticated successfully.
2025-01-27 19:57:04,122 - root - INFO - Database 'buup' already exists.
2025-01-28 10:30:47,386 - root - ERROR - Error while checking user credentials: 172.10.10.88:27017: timed out (configured timeouts: socketTimeoutMS: 20000.0ms, connectTimeoutMS: 20000.0ms), Timeout: 30s, Topology Description: <TopologyDescription id: 67986460c5f8f5babd855048, topology_type: Unknown, servers: [<ServerDescription ('172.10.10.88', 27017) server_type: Unknown, rtt: None, error=NetworkTimeout('172.10.10.88:27017: timed out (configured timeouts: socketTimeoutMS: 20000.0ms, connectTimeoutMS: 20000.0ms)')>]>
2025-01-28 10:31:56,844 - root - INFO - User Manju4 authenticated successfully.
2025-01-28 10:32:38,044 - ApplicationManagment.tasks - ERROR - Error in getTasksForRole: 'ApplicationDataBase' object has no attribute 'checkOrgId'
2025-01-28 10:41:28,623 - root - INFO - User Manju4 authenticated successfully.
2025-01-28 11:01:37,073 - root - INFO - User Manju4 authenticated successfully.
2025-01-28 11:04:19,720 - root - INFO - User Manju4 authenticated successfully.
2025-01-28 11:08:24,451 - root - INFO - User Manju4 authenticated successfully.
2025-01-28 11:11:11,596 - root - INFO - User Manju4 authenticated successfully.
2025-01-28 11:13:02,115 - root - INFO - Database 'buup' already exists.
2025-01-28 11:52:46,025 - root - INFO - User not found.
2025-01-28 11:52:58,325 - root - INFO - User Manju4 authenticated successfully.
2025-01-28 11:59:12,718 - root - INFO - Database 'buup' already exists.
2025-01-28 11:59:57,198 - root - INFO - Database 'buup' already exists.
2025-01-28 12:02:11,115 - root - INFO - Database 'buup' already exists.
2025-01-28 12:02:17,630 - root - INFO - Database 'buup' already exists.
2025-01-28 13:36:27,071 - root - INFO - User Manju4 authenticated successfully.
2025-01-28 13:36:29,959 - root - INFO - Database 'buup' already exists.
2025-01-28 15:27:26,027 - root - INFO - User Manju4 authenticated successfully.
2025-01-28 15:30:14,107 - root - INFO - Database 'buup' already exists.
2025-01-28 15:30:14,111 - ApplicationManagment.tasks - ERROR - Error in getAgents: cannot unpack non-iterable NoneType object
2025-01-28 15:38:43,622 - root - INFO - User Manju4 authenticated successfully.
2025-01-28 15:40:37,061 - root - INFO - User Manju4 authenticated successfully.
2025-01-28 15:41:51,676 - root - INFO - User Manju4 authenticated successfully.
2025-01-28 15:41:58,453 - root - INFO - Database 'buup' already exists.
2025-01-28 15:46:04,586 - root - INFO - User Manju4 authenticated successfully.
2025-01-28 15:46:10,014 - root - INFO - Database 'buup' already exists.
2025-01-28 15:48:00,910 - root - INFO - User Manju4 authenticated successfully.
2025-01-28 15:48:04,216 - root - INFO - Database 'buup' already exists.
2025-01-28 15:49:17,510 - root - INFO - Database 'buup' already exists.
2025-01-28 15:49:17,514 - ApplicationManagment.tasks - ERROR - Error in getAgents: cannot unpack non-iterable NoneType object
2025-01-28 15:56:35,957 - root - INFO - User Manju4 authenticated successfully.
2025-01-28 15:56:46,099 - root - INFO - Database 'buup' already exists.
2025-01-28 15:56:51,649 - root - INFO - Database 'buup' already exists.
2025-01-28 15:56:51,653 - root - ERROR - Error while fetching agents: 'agentName'
2025-01-28 15:59:55,525 - root - INFO - User Manju4 authenticated successfully.
2025-01-28 16:00:03,314 - root - INFO - Database 'buup' already exists.
2025-01-28 16:00:07,414 - root - INFO - Database 'buup' already exists.
2025-01-28 17:11:26,638 - root - INFO - User Manju4 authenticated successfully.
2025-01-28 17:11:35,739 - root - INFO - Database 'buup' already exists.
2025-01-28 17:29:58,363 - root - INFO - Database 'buup' already exists.
2025-01-28 17:30:10,295 - root - INFO - Database 'buup' already exists.
2025-01-28 17:30:22,723 - root - INFO - Database 'buup' already exists.
2025-01-28 17:32:32,556 - root - INFO - Database 'buup' already exists.
2025-01-28 17:38:01,318 - root - INFO - Database 'buup' already exists.
2025-01-28 17:38:11,800 - root - INFO - Database 'buup' already exists.
2025-01-28 18:05:25,344 - root - INFO - User Manju4 authenticated successfully.
2025-01-28 18:05:30,109 - root - INFO - Database 'buup' already exists.
2025-01-28 18:14:39,271 - root - INFO - Creating new database 'xgtm'.
2025-01-28 18:16:03,952 - root - INFO - Database 'buup' already exists.
2025-01-28 18:16:15,458 - root - INFO - Database 'buup' already exists.
2025-01-28 19:20:40,986 - root - INFO - User Manju4 authenticated successfully.
2025-01-28 19:20:46,086 - root - INFO - Database 'buup' already exists.
2025-01-28 19:20:50,360 - root - INFO - Database 'buup' already exists.
2025-01-29 09:32:54,158 - root - INFO - User mani4 authenticated successfully.
2025-01-29 09:36:04,158 - root - INFO - User mani4 authenticated successfully.
2025-01-29 09:38:56,596 - root - INFO - User mani4 authenticated successfully.
2025-01-29 12:50:10,159 - matplotlib.font_manager - WARNING - Matplotlib is building the font cache; this may take a moment.
2025-01-29 12:50:18,837 - matplotlib.font_manager - INFO - Failed to extract font properties from /System/Library/Fonts/LastResort.otf: tuple indices must be integers or slices, not str
2025-01-29 12:50:18,875 - matplotlib.font_manager - INFO - Failed to extract font properties from /System/Library/Fonts/Apple Color Emoji.ttc: In FT2Font: Could not set the fontsize (invalid pixel size; error code 0x17)
2025-01-29 12:50:18,877 - matplotlib.font_manager - INFO - Failed to extract font properties from /System/Library/AssetsV2/com_apple_MobileAsset_Font7/e601d92668cd95cf2002b925cf37be1cd159bce5.asset/AssetData/OctoberIndia.otf: In FT2Font: Can not load face (SFNT font table missing; error code 0x8e)
2025-01-29 12:50:18,898 - matplotlib.font_manager - INFO - Failed to extract font properties from /System/Library/PrivateFrameworks/FontServices.framework/Resources/Reserved/PingFangUI.ttc: In FT2Font: Can not load face (locations (loca) table missing; error code 0x90)
2025-01-29 12:50:18,924 - matplotlib.font_manager - INFO - Failed to extract font properties from /System/Library/Fonts/Supplemental/NISC18030.ttf: In FT2Font: Could not set the fontsize (invalid pixel size; error code 0x17)
2025-01-29 12:50:18,940 - matplotlib.font_manager - INFO - Failed to extract font properties from /System/Library/AssetsV2/com_apple_MobileAsset_Font7/d2c8b613ccb816607409661e33d57b6c0e5b4289.asset/AssetData/NovemberIndia.otf: In FT2Font: Can not load face (SFNT font table missing; error code 0x8e)
2025-01-29 12:50:18,973 - matplotlib.font_manager - INFO - generated new fontManager
2025-01-29 12:58:27,041 - root - INFO - User mani4 authenticated successfully.
2025-01-29 13:01:09,853 - root - INFO - User mani4 authenticated successfully.
2025-01-29 13:01:46,209 - ApplicationManagment.evaluation - INFO - MongoDBHandler initialized for orgId: buup
2025-01-29 13:01:46,330 - ApplicationManagment.evaluation - INFO - Generated process ID: 965bb445
2025-01-29 13:01:46,331 - ApplicationManagment.evaluation - INFO - Evaluation task started with process ID: 965bb445
2025-01-29 13:01:46,487 - ApplicationManagment.Handlers.evaluationHandler - ERROR - An error occurred: Invalid payload format provided
2025-01-29 13:01:46,498 - ApplicationManagment.Handlers.evaluationHandler - ERROR - Error during evaluation of model 9134: Evaluation failed for model
2025-01-29 13:01:46,531 - ApplicationManagment.Handlers.evaluationHandler - ERROR - Unexpected error in evaluation: 
2025-01-29 13:30:24,281 - root - INFO - User mani4 authenticated successfully.
2025-01-29 14:24:10,897 - asyncio - ERROR - Task exception was never retrieved
future: <Task finished name='Task-10' coro=<EvaluationHandler.background_evaluation() done, defined at /Users/apple/Documents/Genx-Platform-Backend/AIPlatform_backend/ApplicationManagment/Handlers/evaluationHandler.py:53> exception=HTTPException(status_code=500, detail='Internal server error: ')>
Traceback (most recent call last):
  File "/Users/apple/Documents/Genx-Platform-Backend/AIPlatform_backend/Database/evaluationSetup.py", line 629, in get_results
    raise HTTPException(status_code=404, detail="Document not found.")
fastapi.exceptions.HTTPException

During handling of the above exception, another exception occurred:

Traceback (most recent call last):
  File "/Users/apple/Documents/Genx-Platform-Backend/AIPlatform_backend/ApplicationManagment/Handlers/evaluationHandler.py", line 161, in background_evaluation
    all_results = await self.mongoHandler.get_results(process_id)
  File "/Users/apple/Documents/Genx-Platform-Backend/AIPlatform_backend/Database/evaluationSetup.py", line 642, in get_results
    raise HTTPException(status_code=500, detail=str(e))
fastapi.exceptions.HTTPException

During handling of the above exception, another exception occurred:

Traceback (most recent call last):
  File "/Users/apple/Documents/Genx-Platform-Backend/AIPlatform_backend/ApplicationManagment/Handlers/evaluationHandler.py", line 182, in background_evaluation
    raise HTTPException(status_code=500, detail=f"Internal server error: {e}")
fastapi.exceptions.HTTPException
2025-01-29 14:27:28,584 - root - INFO - User mani4 authenticated successfully.
2025-01-29 14:35:47,357 - root - INFO - User mani4 authenticated successfully.
2025-01-29 14:41:00,910 - root - INFO - User mani4 authenticated successfully.
2025-01-29 14:41:45,859 - root - INFO - User mani4 authenticated successfully.
2025-01-29 14:44:18,678 - root - INFO - User mani4 authenticated successfully.
2025-01-29 14:44:54,401 - root - ERROR - Error loading YAML data: [Errno 2] No such file or directory: 'C:/Users/Admin/projects/Model_Evaluation/services/Evaluation/payload/result.yml'
2025-01-29 14:44:54,402 - asyncio - ERROR - Unexpected error in metrics calculation: 
2025-01-29 14:46:19,405 - root - INFO - User mani4 authenticated successfully.
2025-01-29 14:46:23,993 - root - ERROR - Error loading YAML data: [Errno 2] No such file or directory: 'C:/Users/Admin/projects/Model_Evaluation/services/Evaluation/payload/result.yml'
2025-01-29 14:46:23,993 - asyncio - ERROR - Unexpected error in metrics calculation: 
2025-01-29 14:52:10,525 - root - INFO - User mani4 authenticated successfully.
2025-01-29 14:52:45,091 - root - INFO - User mani4 authenticated successfully.
2025-01-29 14:56:49,249 - root - INFO - User mani4 authenticated successfully.
2025-01-29 14:59:35,157 - root - INFO - User mani4 authenticated successfully.
2025-01-29 15:04:10,031 - root - INFO - User mani4 authenticated successfully.
2025-01-29 15:04:47,550 - root - INFO - User mani4 authenticated successfully.
2025-01-29 15:13:31,711 - root - INFO - User mani4 authenticated successfully.
2025-01-29 15:16:20,430 - root - INFO - User mani4 authenticated successfully.
2025-01-29 15:17:39,454 - root - INFO - User mani4 authenticated successfully.
2025-01-29 15:20:06,472 - root - INFO - User mani4 authenticated successfully.
2025-01-29 15:24:40,745 - root - INFO - User mani4 authenticated successfully.
2025-01-29 15:27:08,638 - root - INFO - User mani4 authenticated successfully.
2025-01-29 15:31:14,767 - root - INFO - User mani4 authenticated successfully.
2025-01-29 19:34:11,552 - root - ERROR - Invalid or missing 'model' field in the request.
2025-01-29 19:34:11,658 - root - ERROR - Invalid or missing 'model' field in the request.
2025-01-29 19:42:33,521 - root - ERROR - Collection 'LLMModels' does not exist in the database.
2025-01-29 19:42:33,522 - root - ERROR - No records found for model: LLM
2025-01-29 19:42:33,652 - root - ERROR - Collection 'LLMModels' does not exist in the database.
2025-01-29 19:42:33,652 - root - ERROR - No records found for model: LLM
2025-01-29 19:48:24,388 - root - INFO - User mani4 authenticated successfully.
2025-01-29 19:49:50,337 - root - INFO - User mani4 authenticated successfully.
2025-01-29 19:53:53,331 - root - ERROR - Collection 'LLMModels' does not exist in the database.
2025-01-29 19:53:53,334 - root - ERROR - No records found for model: LLM
2025-01-29 19:53:53,431 - root - ERROR - Collection 'LLMModels' does not exist in the database.
2025-01-29 19:53:53,431 - root - ERROR - No records found for model: LLM
2025-01-29 19:54:36,618 - root - ERROR - Collection 'LLMModels' does not exist in the database.
2025-01-29 19:54:36,618 - root - ERROR - No records found for model: LLM
2025-01-29 19:54:36,709 - root - ERROR - Collection 'LLMModels' does not exist in the database.
2025-01-29 19:54:36,709 - root - ERROR - No records found for model: LLM
2025-01-29 19:58:19,734 - root - ERROR - Invalid or missing 'model' field in the request.
2025-01-29 19:58:30,277 - root - ERROR - Collection 'STTModels' does not exist in the database.
2025-01-29 19:58:30,278 - root - ERROR - No records found for model: stt
2025-01-29 19:58:39,894 - root - ERROR - Collection 'LLMModels' does not exist in the database.
2025-01-29 19:58:39,894 - root - ERROR - No records found for model: llm
2025-01-29 19:58:53,645 - root - ERROR - Collection 'LLMModels' does not exist in the database.
2025-01-29 19:58:53,646 - root - ERROR - No records found for model: LLM
2025-01-29 20:01:52,357 - root - ERROR - Collection 'STTModels' does not exist in the database.
2025-01-29 20:01:52,358 - root - ERROR - No records found for model: stt
2025-01-29 20:04:51,945 - root - ERROR - Collection 'LLMModels' does not exist in the database.
2025-01-29 20:04:51,947 - root - ERROR - No records found for model: llm
2025-01-29 20:11:25,377 - root - INFO - User Siva20 authenticated successfully.
2025-01-29 20:11:35,729 - root - ERROR - Collection 'LLMModels' does not exist in the database.
2025-01-29 20:11:35,729 - root - ERROR - No records found for model: llm
2025-01-29 20:11:42,079 - root - ERROR - Collection 'LLMModels' does not exist in the database.
2025-01-29 20:11:42,080 - root - ERROR - No records found for model: llm
2025-01-29 20:11:52,197 - root - ERROR - Collection 'STTModels' does not exist in the database.
2025-01-29 20:11:52,198 - root - ERROR - No records found for model: stt
2025-01-29 20:11:57,073 - root - ERROR - Empty values in fields: model
2025-01-30 09:41:36,887 - root - ERROR - Error while checking user credentials: 172.10.10.62:27017: timed out (configured timeouts: socketTimeoutMS: 20000.0ms, connectTimeoutMS: 20000.0ms), Timeout: 30s, Topology Description: <TopologyDescription id: 679afbda99400ee1c244f644, topology_type: Unknown, servers: [<ServerDescription ('172.10.10.62', 27017) server_type: Unknown, rtt: None, error=NetworkTimeout('172.10.10.62:27017: timed out (configured timeouts: socketTimeoutMS: 20000.0ms, connectTimeoutMS: 20000.0ms)')>]>
2025-01-30 09:42:41,497 - root - ERROR - Error while checking user credentials: 172.10.10.62:27017: timed out (configured timeouts: socketTimeoutMS: 20000.0ms, connectTimeoutMS: 20000.0ms), Timeout: 30s, Topology Description: <TopologyDescription id: 679afc1b99400ee1c244f645, topology_type: Unknown, servers: [<ServerDescription ('172.10.10.62', 27017) server_type: Unknown, rtt: None, error=NetworkTimeout('172.10.10.62:27017: timed out (configured timeouts: socketTimeoutMS: 20000.0ms, connectTimeoutMS: 20000.0ms)')>]>
2025-01-30 09:44:10,519 - root - ERROR - Error while checking user credentials: 172.10.10.62:27017: timed out (configured timeouts: socketTimeoutMS: 20000.0ms, connectTimeoutMS: 20000.0ms), Timeout: 30s, Topology Description: <TopologyDescription id: 679afc7499400ee1c244f646, topology_type: Unknown, servers: [<ServerDescription ('172.10.10.62', 27017) server_type: Unknown, rtt: None, error=NetworkTimeout('172.10.10.62:27017: timed out (configured timeouts: socketTimeoutMS: 20000.0ms, connectTimeoutMS: 20000.0ms)')>]>
2025-01-30 09:45:47,684 - root - ERROR - Error while checking user credentials: 172.10.10.62:27017: timed out (configured timeouts: socketTimeoutMS: 20000.0ms, connectTimeoutMS: 20000.0ms), Timeout: 30s, Topology Description: <TopologyDescription id: 679afcd599400ee1c244f647, topology_type: Unknown, servers: [<ServerDescription ('172.10.10.62', 27017) server_type: Unknown, rtt: None, error=NetworkTimeout('172.10.10.62:27017: timed out (configured timeouts: socketTimeoutMS: 20000.0ms, connectTimeoutMS: 20000.0ms)')>]>
2025-01-30 09:47:32,609 - root - ERROR - Error while checking user credentials: 172.10.10.62:27017: timed out (configured timeouts: socketTimeoutMS: 20000.0ms, connectTimeoutMS: 20000.0ms), Timeout: 30s, Topology Description: <TopologyDescription id: 679afd3edac9dff427afe855, topology_type: Unknown, servers: [<ServerDescription ('172.10.10.62', 27017) server_type: Unknown, rtt: None, error=NetworkTimeout('172.10.10.62:27017: timed out (configured timeouts: socketTimeoutMS: 20000.0ms, connectTimeoutMS: 20000.0ms)')>]>
2025-01-30 09:48:02,709 - root - ERROR - Error while checking user credentials: 172.10.10.62:27017: timed out (configured timeouts: socketTimeoutMS: 20000.0ms, connectTimeoutMS: 20000.0ms), Timeout: 30s, Topology Description: <TopologyDescription id: 679afd5cdac9dff427afe856, topology_type: Unknown, servers: [<ServerDescription ('172.10.10.62', 27017) server_type: Unknown, rtt: None, error=NetworkTimeout('172.10.10.62:27017: timed out (configured timeouts: socketTimeoutMS: 20000.0ms, connectTimeoutMS: 20000.0ms)')>]>
2025-01-30 09:50:52,152 - root - INFO - User Siva20 authenticated successfully.
2025-01-30 09:51:16,436 - root - INFO - User mani4 authenticated successfully.
2025-01-30 09:51:55,543 - root - INFO - User mani4 authenticated successfully.
2025-01-30 16:32:07,018 - root - ERROR - Error while checking user credentials: 192.168.0.77:27017: timed out (configured timeouts: socketTimeoutMS: 20000.0ms, connectTimeoutMS: 20000.0ms), Timeout: 30s, Topology Description: <TopologyDescription id: 679b5c1058d50b5f9e055b6c, topology_type: Unknown, servers: [<ServerDescription ('192.168.0.77', 27017) server_type: Unknown, rtt: None, error=NetworkTimeout('192.168.0.77:27017: timed out (configured timeouts: socketTimeoutMS: 20000.0ms, connectTimeoutMS: 20000.0ms)')>]>
2025-01-30 16:33:33,902 - root - INFO - User mani4 authenticated successfully.
2025-01-30 16:36:49,209 - root - ERROR - Error while checking user credentials: 192.168.0.77:27017: timed out (configured timeouts: socketTimeoutMS: 20000.0ms, connectTimeoutMS: 20000.0ms), Timeout: 30s, Topology Description: <TopologyDescription id: 679b5d2b1c816e348b2c8e66, topology_type: Unknown, servers: [<ServerDescription ('192.168.0.77', 27017) server_type: Unknown, rtt: None, error=NetworkTimeout('192.168.0.77:27017: timed out (configured timeouts: socketTimeoutMS: 20000.0ms, connectTimeoutMS: 20000.0ms)')>]>
2025-01-30 16:41:06,934 - root - ERROR - Error while checking user credentials: 192.168.0.66:27017: timed out (configured timeouts: socketTimeoutMS: 20000.0ms, connectTimeoutMS: 20000.0ms), Timeout: 30s, Topology Description: <TopologyDescription id: 679b5e2cdf4a9d0484ffc5b0, topology_type: Unknown, servers: [<ServerDescription ('192.168.0.66', 27017) server_type: Unknown, rtt: None, error=NetworkTimeout('192.168.0.66:27017: timed out (configured timeouts: socketTimeoutMS: 20000.0ms, connectTimeoutMS: 20000.0ms)')>]>
2025-01-30 16:41:57,087 - root - ERROR - Error while checking user credentials: 192.168.0.66:27017: timed out (configured timeouts: socketTimeoutMS: 20000.0ms, connectTimeoutMS: 20000.0ms), Timeout: 30s, Topology Description: <TopologyDescription id: 679b5e5edf4a9d0484ffc5b1, topology_type: Unknown, servers: [<ServerDescription ('192.168.0.66', 27017) server_type: Unknown, rtt: None, error=NetworkTimeout('192.168.0.66:27017: timed out (configured timeouts: socketTimeoutMS: 20000.0ms, connectTimeoutMS: 20000.0ms)')>]>
2025-01-30 16:45:09,803 - root - ERROR - Error while checking user credentials: 192.168.0.66:27017: timed out (configured timeouts: socketTimeoutMS: 20000.0ms, connectTimeoutMS: 20000.0ms), Timeout: 30s, Topology Description: <TopologyDescription id: 679b5f1fdf4a9d0484ffc5b2, topology_type: Unknown, servers: [<ServerDescription ('192.168.0.66', 27017) server_type: Unknown, rtt: None, error=NetworkTimeout('192.168.0.66:27017: timed out (configured timeouts: socketTimeoutMS: 20000.0ms, connectTimeoutMS: 20000.0ms)')>]>
2025-01-30 16:46:03,523 - root - ERROR - Error while checking user credentials: 192.168.0.66:27017: timed out (configured timeouts: socketTimeoutMS: 20000.0ms, connectTimeoutMS: 20000.0ms), Timeout: 30s, Topology Description: <TopologyDescription id: 679b5f55a7e04b685e112060, topology_type: Unknown, servers: [<ServerDescription ('192.168.0.66', 27017) server_type: Unknown, rtt: None, error=NetworkTimeout('192.168.0.66:27017: timed out (configured timeouts: socketTimeoutMS: 20000.0ms, connectTimeoutMS: 20000.0ms)')>]>
2025-01-30 16:47:14,805 - root - ERROR - Error while checking user credentials: 192.168.0.66:27017: timed out (configured timeouts: socketTimeoutMS: 20000.0ms, connectTimeoutMS: 20000.0ms), Timeout: 30s, Topology Description: <TopologyDescription id: 679b5f9ca7e04b685e112061, topology_type: Unknown, servers: [<ServerDescription ('192.168.0.66', 27017) server_type: Unknown, rtt: None, error=NetworkTimeout('192.168.0.66:27017: timed out (configured timeouts: socketTimeoutMS: 20000.0ms, connectTimeoutMS: 20000.0ms)')>]>
2025-01-30 16:48:38,292 - root - ERROR - Error while checking user credentials: 192.168.0.66:27017: timed out (configured timeouts: socketTimeoutMS: 20000.0ms, connectTimeoutMS: 20000.0ms), Timeout: 30s, Topology Description: <TopologyDescription id: 679b5ff0a7e04b685e112062, topology_type: Unknown, servers: [<ServerDescription ('192.168.0.66', 27017) server_type: Unknown, rtt: None, error=NetworkTimeout('192.168.0.66:27017: timed out (configured timeouts: socketTimeoutMS: 20000.0ms, connectTimeoutMS: 20000.0ms)')>]>
2025-01-30 16:59:10,324 - root - ERROR - Error while checking user credentials: 192.168.0.66:27017: timed out (configured timeouts: socketTimeoutMS: 20000.0ms, connectTimeoutMS: 20000.0ms), Timeout: 30s, Topology Description: <TopologyDescription id: 679b6268b9f37fbe12b1905e, topology_type: Unknown, servers: [<ServerDescription ('192.168.0.66', 27017) server_type: Unknown, rtt: None, error=NetworkTimeout('192.168.0.66:27017: timed out (configured timeouts: socketTimeoutMS: 20000.0ms, connectTimeoutMS: 20000.0ms)')>]>
2025-01-30 17:02:12,585 - root - ERROR - Error while checking user credentials: 192.168.0.66:27017: timed out (configured timeouts: socketTimeoutMS: 20000.0ms, connectTimeoutMS: 20000.0ms), Timeout: 30s, Topology Description: <TopologyDescription id: 679b631eb9f37fbe12b1905f, topology_type: Unknown, servers: [<ServerDescription ('192.168.0.66', 27017) server_type: Unknown, rtt: None, error=NetworkTimeout('192.168.0.66:27017: timed out (configured timeouts: socketTimeoutMS: 20000.0ms, connectTimeoutMS: 20000.0ms)')>]>
2025-01-30 17:02:56,951 - root - ERROR - Error while checking user credentials: 192.168.0.66:27017: timed out (configured timeouts: socketTimeoutMS: 20000.0ms, connectTimeoutMS: 20000.0ms), Timeout: 30s, Topology Description: <TopologyDescription id: 679b634ab9f37fbe12b19060, topology_type: Unknown, servers: [<ServerDescription ('192.168.0.66', 27017) server_type: Unknown, rtt: None, error=NetworkTimeout('192.168.0.66:27017: timed out (configured timeouts: socketTimeoutMS: 20000.0ms, connectTimeoutMS: 20000.0ms)')>]>
2025-01-30 17:07:51,572 - root - ERROR - Error while checking user credentials: 192.168.0.66:27017: timed out (configured timeouts: socketTimeoutMS: 20000.0ms, connectTimeoutMS: 20000.0ms), Timeout: 30s, Topology Description: <TopologyDescription id: 679b6471925776d06e5e1a7d, topology_type: Unknown, servers: [<ServerDescription ('192.168.0.66', 27017) server_type: Unknown, rtt: None, error=NetworkTimeout('192.168.0.66:27017: timed out (configured timeouts: socketTimeoutMS: 20000.0ms, connectTimeoutMS: 20000.0ms)')>]>
2025-01-30 17:09:27,963 - root - ERROR - Error while checking user credentials: 192.168.0.66:27017: timed out (configured timeouts: socketTimeoutMS: 20000.0ms, connectTimeoutMS: 20000.0ms), Timeout: 30s, Topology Description: <TopologyDescription id: 679b64d1925776d06e5e1a7e, topology_type: Unknown, servers: [<ServerDescription ('192.168.0.66', 27017) server_type: Unknown, rtt: None, error=NetworkTimeout('192.168.0.66:27017: timed out (configured timeouts: socketTimeoutMS: 20000.0ms, connectTimeoutMS: 20000.0ms)')>]>
2025-01-30 17:10:40,476 - root - ERROR - Error while checking user credentials: 192.168.0.66:27017: timed out (configured timeouts: socketTimeoutMS: 20000.0ms, connectTimeoutMS: 20000.0ms), Timeout: 30s, Topology Description: <TopologyDescription id: 679b651a925776d06e5e1a7f, topology_type: Unknown, servers: [<ServerDescription ('192.168.0.66', 27017) server_type: Unknown, rtt: None, error=NetworkTimeout('192.168.0.66:27017: timed out (configured timeouts: socketTimeoutMS: 20000.0ms, connectTimeoutMS: 20000.0ms)')>]>
2025-01-30 17:17:54,918 - root - ERROR - Error while checking user credentials: 192.168.0.66:27017: timed out (configured timeouts: socketTimeoutMS: 20000.0ms, connectTimeoutMS: 20000.0ms), Timeout: 30s, Topology Description: <TopologyDescription id: 679b66cc925776d06e5e1a80, topology_type: Unknown, servers: [<ServerDescription ('192.168.0.66', 27017) server_type: Unknown, rtt: None, error=NetworkTimeout('192.168.0.66:27017: timed out (configured timeouts: socketTimeoutMS: 20000.0ms, connectTimeoutMS: 20000.0ms)')>]>
2025-01-30 17:22:41,740 - root - ERROR - Error while checking user credentials: 192.168.0.66:27017: timed out (configured timeouts: socketTimeoutMS: 20000.0ms, connectTimeoutMS: 20000.0ms), Timeout: 30s, Topology Description: <TopologyDescription id: 679b67ebadf8077b2ef0ccb8, topology_type: Unknown, servers: [<ServerDescription ('192.168.0.66', 27017) server_type: Unknown, rtt: None, error=NetworkTimeout('192.168.0.66:27017: timed out (configured timeouts: socketTimeoutMS: 20000.0ms, connectTimeoutMS: 20000.0ms)')>]>
2025-01-30 17:25:37,444 - root - ERROR - Error while checking user credentials: 192.168.0.66:27017: timed out (configured timeouts: socketTimeoutMS: 20000.0ms, connectTimeoutMS: 20000.0ms), Timeout: 30s, Topology Description: <TopologyDescription id: 679b689b53319ceadb04fd5c, topology_type: Unknown, servers: [<ServerDescription ('192.168.0.66', 27017) server_type: Unknown, rtt: None, error=NetworkTimeout('192.168.0.66:27017: timed out (configured timeouts: socketTimeoutMS: 20000.0ms, connectTimeoutMS: 20000.0ms)')>]>
2025-01-30 17:38:02,506 - root - ERROR - Error Log In: 'deviceHash'
2025-01-30 17:38:05,786 - root - ERROR - Error Log In: 'deviceHash'
2025-01-30 17:39:09,061 - root - INFO - User mani4 authenticated successfully.
2025-01-30 17:39:28,334 - root - INFO - User mani4 authenticated successfully.
2025-01-30 17:41:00,880 - root - ERROR - Error loading YAML data: [Errno 2] No such file or directory: 'C:/Users/Admin/projects/Model_Evaluation/services/Evaluation/payload/result.yml'
2025-01-30 17:41:00,881 - asyncio - ERROR - Unexpected error in metrics calculation: 
2025-01-30 17:43:43,712 - root - INFO - User mani4 authenticated successfully.
2025-01-30 17:44:54,999 - ApplicationManagment.evaluation - INFO - MongoDBHandler initialized for orgId: buup
2025-01-30 17:44:55,287 - ApplicationManagment.evaluation - INFO - Generated process ID: fdb37583
2025-01-30 17:44:55,288 - ApplicationManagment.evaluation - INFO - Evaluation task started with process ID: fdb37583
2025-01-30 17:44:55,473 - ApplicationManagment.Handlers.evaluationHandler - ERROR - An error occurred: Invalid payload format provided
2025-01-30 17:44:55,487 - ApplicationManagment.Handlers.evaluationHandler - ERROR - Error during evaluation of model 9134: Evaluation failed for model
2025-01-30 17:44:55,559 - ApplicationManagment.Handlers.evaluationHandler - ERROR - Unexpected error in evaluation: 
2025-01-30 17:48:15,616 - root - INFO - User mani4 authenticated successfully.
2025-01-30 17:50:41,813 - root - INFO - User mani4 authenticated successfully.
2025-01-30 17:51:49,332 - asyncio - ERROR - Task exception was never retrieved
future: <Task finished name='Task-25' coro=<EvaluationHandler.background_evaluation() done, defined at /Users/apple/Documents/Genx-Platform-Backend/AIPlatform_backend/ApplicationManagment/Handlers/evaluationHandler.py:53> exception=HTTPException(status_code=500, detail='Internal server error: ')>
Traceback (most recent call last):
  File "/Users/apple/Documents/Genx-Platform-Backend/AIPlatform_backend/Database/evaluationSetup.py", line 633, in get_results
    raise HTTPException(status_code=404, detail="Document not found.")
fastapi.exceptions.HTTPException

During handling of the above exception, another exception occurred:

Traceback (most recent call last):
  File "/Users/apple/Documents/Genx-Platform-Backend/AIPlatform_backend/ApplicationManagment/Handlers/evaluationHandler.py", line 161, in background_evaluation
    all_results = await self.mongoHandler.get_results(process_id)
  File "/Users/apple/Documents/Genx-Platform-Backend/AIPlatform_backend/Database/evaluationSetup.py", line 646, in get_results
    raise HTTPException(status_code=500, detail=str(e))
fastapi.exceptions.HTTPException

During handling of the above exception, another exception occurred:

Traceback (most recent call last):
  File "/Users/apple/Documents/Genx-Platform-Backend/AIPlatform_backend/ApplicationManagment/Handlers/evaluationHandler.py", line 182, in background_evaluation
    raise HTTPException(status_code=500, detail=f"Internal server error: {e}")
fastapi.exceptions.HTTPException
2025-01-30 17:52:15,297 - root - INFO - User mani4 authenticated successfully.
2025-01-30 18:09:51,218 - root - INFO - Fetched 1 records from collection 'LLMModels'.
2025-01-30 18:09:51,218 - root - INFO - Model details fetched successfully for model: LLM.
2025-01-30 19:14:18,993 - root - ERROR - Error while checking user credentials: 192.168.0.66:27017: timed out (configured timeouts: socketTimeoutMS: 20000.0ms, connectTimeoutMS: 20000.0ms), Timeout: 30s, Topology Description: <TopologyDescription id: 679b8214a0afe9331521c6eb, topology_type: Unknown, servers: [<ServerDescription ('192.168.0.66', 27017) server_type: Unknown, rtt: None, error=NetworkTimeout('192.168.0.66:27017: timed out (configured timeouts: socketTimeoutMS: 20000.0ms, connectTimeoutMS: 20000.0ms)')>]>
2025-01-30 19:16:20,746 - root - INFO - User mani4 authenticated successfully.
